Workbook

Sheet Read Me
A1: Style Sphere — Omnichannel Inventory Model
A3: Purpose | B3: Implements the Fixed-Charge / Big-M / Goal-Programming models built for the Style Sphere case (ship-from-store enablement, pooling limit, cost vs. service trade-offs).
A5: How to use this file
B6: • Data sheet — every number from Exhibits 1-6, transcribed exactly. Change anything here and downstream sheets recalc.
B7: • Baseline Model — the full Fixed-Charge transportation LP (Model 1). Blue cells (x_ij, y_s) are Solver's decision variables.
B8: • To re-solve: Data tab -> Solver -> Set Objective = Total Cost cell (minimize) -> By Changing: the blue x and y ranges -> Subject to: the constraint rows shown -> check 'Make Unconstrained Variables Non-Negative' -> Solving Method: Simplex LP -> Solve.
B9: • Store Enablement Economics — Model 2: payback period for turning ON each store individually (pure fulfilment-cost savings).
B10: • Strategy Comparison — three pre-solved scenarios (Separated / Selective / Highly Pooled) side by side.
B11: • Pooling Sensitivity — Model 4: cost & service as the pooling limit p rises from 30% to 50%.
B12: • Goal Programming — Model 3: multi-goal version (fill rate, store protection, cost, markdown) with weighted deviation variables. Solver-ready.
B13: • Risk (Expected Value) — Model 5 equations turned into expected-value formulas from Exhibits 5-6 (a full 1,000+ trial Monte Carlo needs a script; this sheet gives the single-point expected-value estimate that a simulation would center on).
A15: Color key
A16: Blue text | B16: Hardcoded input / Solver decision variable — edit freely
A17: Black text | B17: Live formula — do not overwrite
A18: Yellow fill | B18: Key assumption you should sanity-check before trusting the output
A20: Key assumption flagged
B21: The case gives no amortization horizon for the one-time store-enablement cost (Exhibit 1). Rather than guess a number of months, the Baseline Model treats enablement as a separate CAPITAL decision, evaluated on the Store Enablement Economics sheet via payback period — this is the standard way capex decisions are made and avoids an arbitrary amortization assumption.

Sheet Data
A1: Data — Exhibits 1 to 6
A3: Exhibit 1. Warehouses and Stores
A4: Location | B4: Type | C4: Local Demand | D4: Storage/Throughput Capacity | E4: Enablement Cost (Rs lakh)
A5: W1 North | B5: Warehouse | D5: 28000
A6: W2 South | B6: Warehouse | D6: 26000
A7: S1 | B7: Store | C7: 5000 | D7: 7000 | E7: 12
A8: S2 | B8: Store | C8: 4500 | D8: 6500 | E8: 10
A9: S3 | B9: Store | C9: 6200 | D9: 8000 | E9: 14
A10: S4 | B10: Store | C10: 3800 | D10: 5500 | E10: 9
A11: S5 | B11: Store | C11: 5500 | D11: 7500 | E11: 13
A13: Exhibit 2. Online Regional Demand
A14: Region | B14: Mean Demand/Month | C14: Std Dev | D14: Target Delivery Share <=2 days
A15: North | B15: 9000 | C15: 1620 | D15: 0.9
A16: West | B16: 7500 | C16: 1350 | D16: 0.85
A17: South | B17: 10000 | C17: 1800 | D17: 0.9
A18: East | B18: 6500 | C18: 1170 | D18: 0.85
A20: Exhibit 3. Average Online Fulfilment Cost per Order (Rs)
A21: Facility | B21: North | C21: West | D21: South | E21: East
A22: W1 | B22: 58 | C22: 72 | D22: 105 | E22: 92
A23: W2 | B23: 96 | C23: 88 | D23: 55 | E23: 78
A24: S1 | B24: 62 | C24: 70 | D24: 90 | E24: 87
A25: S2 | B25: 68 | C25: 61 | D25: 95 | E25: 87
A26: S3 | B26: 98 | C26: 84 | D26: 60 | E26: 73
A27: S4 | B27: 82 | C27: 75 | D27: 78 | E27: 65
A28: S5 | B28: 76 | C28: 69 | D28: 71 | E28: 68
A30: Exhibit 4. Inventory Economics
A31: Outcome | B31: Planning Value (Rs)
A32: Store stockout contribution loss (/unit) | B32: 420
A33: Online lost-sale contribution loss (/order) | B33: 360
A34: End-of-month excess inventory holding (/unit) | B34: 35
A35: Markdown on aged fashion inventory (/unit) | B35: 110
A36: Store-to-store transfer (/unit) | B36: 55
A38: Exhibit 5. Demand Uncertainty
A39: Input | B39: Uncertainty (as % of mean, or probability)
A40: Store demand std dev | B40: 0.12
A41: Online regional demand std dev | B41: 0.18
A42: Promotional surge probability (x1.25 online demand) | B42: 0.15
A44: Exhibit 6. Returns
A45: Condition | B45: Probability | C45: Online Return Rate
A46: Low | B46: 0.25 | C46: 0.1
...

Sheet Baseline Model
A1: Baseline Model — Fixed-Charge Transportation LP (Model 1)
A3: Step 1 — Facility capacity & cost per order to each region (pulled live from Data sheet)
A4: Facility | B4: Capacity | C4: North | D4: West | E4: South | F4: East | G4: Enabled? (y) | H4: Enable Cost (Rs)
A5: W1 | B5: =Data!D5 -> 28000 | C5: =Data!B22 -> 58 | D5: =Data!C22 -> 72 | E5: =Data!D22 -> 105 | F5: =Data!E22 -> 92 | G5: n/a | H5: -
A6: W2 | B6: =Data!D6 -> 26000 | C6: =Data!B23 -> 96 | D6: =Data!C23 -> 88 | E6: =Data!D23 -> 55 | F6: =Data!E23 -> 78 | G6: n/a | H6: -
A7: S1 | B7: =Data!D7 -> 7000 | C7: =Data!B24 -> 62 | D7: =Data!C24 -> 70 | E7: =Data!D24 -> 90 | F7: =Data!E24 -> 87 | G7: 1 | H7: =Data!E7*100000 -> 1200000
A8: S2 | B8: =Data!D8 -> 6500 | C8: =Data!B25 -> 68 | D8: =Data!C25 -> 61 | E8: =Data!D25 -> 95 | F8: =Data!E25 -> 87 | G8: 1 | H8: =Data!E8*100000 -> 1000000
A9: S3 | B9: =Data!D9 -> 8000 | C9: =Data!B26 -> 98 | D9: =Data!C26 -> 84 | E9: =Data!D26 -> 60 | F9: =Data!E26 -> 73 | G9: 1 | H9: =Data!E9*100000 -> 1400000
A10: S4 | B10: =Data!D10 -> 5500 | C10: =Data!B27 -> 82 | D10: =Data!C27 -> 75 | E10: =Data!D27 -> 78 | F10: =Data!E27 -> 65 | G10: 1 | H10: =Data!E10*100000 -> 900000
A11: S5 | B11: =Data!D11 -> 7500 | C11: =Data!B28 -> 76 | D11: =Data!C28 -> 69 | E11: =Data!D28 -> 71 | F11: =Data!E28 -> 68 | G11: 1 | H11: =Data!E11*100000 -> 1300000
A13: Step 2 — Decision variables: units/orders shipped, facility -> region (x_ij). Blue = Solver changes these.
A14: Facility | B14: North | C14: West | D14: South | E14: East | F14: Total shipped | G14: Capacity | H14: Slack
A15: W1 | B15: 9000 | C15: 7500 | D15: 0 | E15: 0 | F15: =SUM(B15:E15) -> 16500 | G15: =B5 -> 28000 | H15: =G15-F15 -> 11500
A16: W2 | B16: 0 | C16: 0 | D16: 10000 | E16: 6500 | F16: =SUM(B16:E16) -> 16500 | G16: =B6 -> 26000 | H16: =G16-F16 -> 9500
A17: S1 | B17: 0 | C17: 0 | D17: 0 | E17: 0 | F17: =SUM(B17:E17) -> 0 | G17: =B7 -> 7000 | H17: =G17-F17 -> 7000
A18: S2 | B18: 0 | C18: 0 | D18: 0 | E18: 0 | F18: =SUM(B18:E18) -> 0 | G18: =B8 -> 6500 | H18: =G18-F18 -> 6500
A19: S3 | B19: 0 | C19: 0 | D19: 0 | E19: 0 | F19: =SUM(B19:E19) -> 0 | G19: =B9 -> 8000 | H19: =G19-F19 -> 8000
A20: S4 | B20: 0 | C20: 0 | D20: 0 | E20: 0 | F20: =SUM(B20:E20) -> 0 | G20: =B10 -> 5500 | H20: =G20-F20 -> 5500
A21: S5 | B21: 0 | C21: 0 | D21: 0 | E21: 0 | F21: =SUM(B21:E21) -> 0 | G21: =B11 -> 7500 | H21: =G21-F21 -> 7500
A23: Step 3 — Demand balance check by region (must be = 0, i.e. demand fully met, or watch 'Lost' column)
A24: Region | B24: Demand | C24: Total Shipped (all facilities) | D24: Lost sales | E24: Fill rate
A25: North | B25: =Data!B15 -> 9000 | C25: =SUM(B15:B21) -> 9000 | D25: =MAX(0,B25-C25) -> 0 | E25: =1-D25/B25 -> 1
A26: West | B26: =Data!B16 -> 7500 | C26: =SUM(C15:C21) -> 7500 | D26: =MAX(0,B26-C26) -> 0 | E26: =1-D26/B26 -> 1
A27: South | B27: =Data!B17 -> 10000 | C27: =SUM(D15:D21) -> 10000 | D27: =MAX(0,B27-C27) -> 0 | E27: =1-D27/B27 -> 1
A28: East | B28: =Data!B18 -> 6500 | C28: =SUM(E15:E21) -> 6500 | D28: =MAX(0,B28-C28) -> 0 | E28: =1-D28/B28 -> 1
A30: Step 4 — Store pooling-cap & local-demand-protection constraints
A31: Store | B31: Online shipped (sum) | C31: Pooling limit p x Capacity x y | D31: Slack (must be >=0) | E31: Local demand | F31: Local + Online | G31: Capacity | H31: Slack (must be >=0)
A32: S1 | B32: =F17 -> 0 | C32: =Data!$B$56*B7*G7 -> 2100 | D32: =C32-B32 -> 2100 | E32: =Data!C7 -> 5000 | F32: =E32+B32 -> 5000 | G32: =B7 -> 7000 | H32: =G32-F32 -> 2000
A33: S2 | B33: =F18 -> 0 | C33: =Data!$B$56*B8*G8 -> 1950 | D33: =C33-B33 -> 1950 | E33: =Data!C8 -> 4500 | F33: =E33+B33 -> 4500 | G33: =B8 -> 6500 | H33: =G33-F33 -> 2000
A34: S3 | B34: =F19 -> 0 | C34: =Data!$B$56*B9*G9 -> 2400 | D34: =C34-B34 -> 2400 | E34: =Data!C9 -> 6200 | F34: =E34+B34 -> 6200 | G34: =B9 -> 8000 | H34: =G34-F34 -> 1800
A35: S4 | B35: =F20 -> 0 | C35: =Data!$B$56*B10*G10 -> 1650 | D35: =C35-B35 -> 1650 | E35: =Data!C10 -> 3800 | F35: =E35+B35 -> 3800 | G35: =B10 -> 5500 | H35: =G35-F35 -> 1700
A36: S5 | B36: =F21 -> 0 | C36: =Data!$B$56*B11*G11 -> 2250 | D36: =C36-B36 -> 2250 | E36: =Data!C11 -> 5500 | F36: =E36+B36 -> 5500 | G36: =B11 -> 7500 | H36: =G36-F36 -> 2000
A38: Step 5 — Objective (Solver target: minimize)
A39: Fulfilment cost (Rs/month) | B39: =SUMPRODUCT(C5:C11,B15:B21)+SUMPRODUCT(D5:D11,C15:C21)+SUMPRODUCT(E5:E11,D15:D21)+SUMPRODUCT(F5:F11,E15:E21) -> 2119000
A40: Online lost-sale penalty (Rs/month) | B40: =SUM(D25:D28)*Data!B33 -> 0
A41: TOTAL MONTHLY COST (Solver Objective Cell) | B41: =B39+B40 -> 2119000
A42: Overall online fill rate | B42: =1-SUM(D25:D28)/SUM(B25:B28) -> 1
A44: Solver setup
B45: Set Objective: B41 (Min)
B46: By Changing Variable Cells: B15:E21 (the x_ij grid) and G7:G11 (the y_s binaries for stores)
...

Sheet Store Enablement Economics
A1: Model 2 — Store Enablement Economics (Fixed-Charge Payback)
B3: Method: solve the pure allocation LP twice - once with NO stores enabled (Separated), once with ONLY store s enabled at pooling limit p=30% - the difference in fulfilment cost is store s's monthly value.
A5: Separated baseline fulfilment cost (Rs/month, from Model 1 with all y_s = 0): | C5: 2119000
A7: Store | B7: Local Demand | C7: Capacity | D7: Enable Cost (Rs) | E7: Monthly Saving from enabling alone (Rs) | F7: Payback (months) | G7: Verdict
A8: S1 | B8: =Data!C7 -> 5000 | C8: =Data!D7 -> 7000 | D8: =Data!E7*100000 -> 1200000 | E8: 4000 | F8: =IF(E8>0,D8/E8,"n/a") -> 300 | G8: =IF(F8="n/a","No standalone case",IF(F8<=E14,"Enable - pays back","Marginal on cost alone")) -> Marginal on cost alone
A9: S2 | B9: =Data!C8 -> 4500 | C9: =Data!D8 -> 6500 | D9: =Data!E8*100000 -> 1000000 | E9: 21450 | F9: =IF(E9>0,D9/E9,"n/a") -> 46.620047 | G9: =IF(F9="n/a","No standalone case",IF(F9<=E14,"Enable - pays back","Marginal on cost alone")) -> Enable - pays back
A10: S3 | B10: =Data!C9 -> 6200 | C10: =Data!D9 -> 8000 | D10: =Data!E9*100000 -> 1400000 | E10: 9000 | F10: =IF(E10>0,D10/E10,"n/a") -> 155.55556 | G10: =IF(F10="n/a","No standalone case",IF(F10<=E14,"Enable - pays back","Marginal on cost alone")) -> Marginal on cost alone
A11: S4 | B11: =Data!C10 -> 3800 | C11: =Data!D10 -> 5500 | D11: =Data!E10*100000 -> 900000 | E11: 21450 | F11: =IF(E11>0,D11/E11,"n/a") -> 41.958042 | G11: =IF(F11="n/a","No standalone case",IF(F11<=E14,"Enable - pays back","Marginal on cost alone")) -> Enable - pays back
A12: S5 | B12: =Data!C11 -> 5500 | C12: =Data!D11 -> 7500 | D12: =Data!E11*100000 -> 1300000 | E12: 20000 | F12: =IF(E12>0,D12/E12,"n/a") -> 65 | G12: =IF(F12="n/a","No standalone case",IF(F12<=E14,"Enable - pays back","Marginal on cost alone")) -> Marginal on cost alone
A14: Payback hurdle (months) — management's capex threshold: | E14: 48
B15: Note: on pure fulfilment-cost economics alone, most stores exceed a typical 24-48 month hurdle - the real case for enabling S2/S4/S5 rests on SERVICE value (stockout & lost-sale risk reduction under demand surges / warehouse disruption - see Risk sheet), not fulfilment-cost savings alone.

Sheet Strategy Comparison
A1: Deliverable 3 — Separated vs Selective vs Highly Pooled
B3: Each column = one full solve of Model 1 (see equations doc) under different y_s / p settings.
A5: Metric | B5: Separated (all y_s = 0) | C5: Selective (cost-optimal y_s, p=30%) | D5: Highly Pooled (all y_s=1, p=50%)
A6: Stores enabled | B6: None | C6: None (cost-optimal at p=30% enables none - see note) | D6: S1,S2,S3,S4,S5
A7: Fulfilment cost (Rs/month) | B7: 2119000 | C7: 2119000 | D7: 2041900
A8: Saving vs Separated (Rs/month) | B8: 0 | C8: 0 | D8: 77100
A9: Online lost sales (units) | B9: 0 | C9: 0 | D9: 0
A10: Online fill rate | B10: 1 | C10: 1 | D10: 1
A11: Amortised enablement cost (12 mo, Rs/month) [Model 1 opt.] | B11: 0 | C11: 0 | D11: 483333
A12: Store online-capacity used (units) | B12: 0 | C12: 0 | D12: 9500
A13: Warehouse capacity headroom (units) | B13: 15500 | C13: 15500 | D13: 6000
A15: Key takeaway
B16: Because total warehouse capacity (54,000) already exceeds total online demand (33,000) at the mean, pure cost-minimization barely favors ship-from-store (~Rs 77,000/month max saving, against Rs 9-14 lakh one-time enablement costs). The service-resilience case (protecting fill rate during promo surges / warehouse disruption - see Risk sheet) is the real argument for enabling S2, S4 and S5.

Sheet Pooling Sensitivity
A1: Deliverable 6 — Sensitivity to the Pooling Limit p (Model 4)
B3: All stores enabled; only the pooling limit p changes. Values below come from re-solving Model 1 at each p (the small deltas confirm most stores' capacity is already the binding constraint by p=40%).
A5: Pooling limit p | B5: 30% | C5: 40% | D5: 50%
A6: Fulfilment cost (Rs/month) | B6: 2043100 | C6: 2041900 | D6: 2041900
A7: Saving vs Separated (Rs/month) | B7: 75900 | C7: 77100 | D7: 77100
A8: Online fill rate | B8: 1 | C8: 1 | D8: 1
A9: Store online capacity committed (units) | B9: 10350 | C9: 13800 | D9: 17250
A10: Store capacity used (units, from solve) | B10: 9500 | C10: 9500 | D10: 9500
A11: Warehouse capacity freed up (units) | B11: 9500 | C11: 9500 | D11: 9500
A14: Reading this table (Deliverable 7 material)
B15: Cost savings plateau almost immediately after p=30% -> 40% (Rs 75,900 to Rs 77,100 - a ~1.6% further gain), while committed store online-capacity keeps climbing (10,350 -> 17,250 units) with no extra fulfilment benefit under mean demand. This is the classic diminishing-returns 'knee': raising the pooling limit beyond ~40% adds store-availability RISK (less capacity reserved for walk-in) without a matching cost or service payoff under normal conditions - its value only shows up during promo surges / disruption (see Risk sheet). Recommendation: hold p at 30-40%, revisit only when online demand growth (~22% YoY per Exhibit 3) pushes total demand materially closer to combined capacity.

Sheet Goal Programming
A1: Model 3 — Goal Programming (weighted deviations)
B3: Solver-ready template. Deviation variables (blue) are Solver's decision variables alongside the x_ij grid on the Baseline Model sheet. Weights (yellow) are policy choices - raise a weight to make Solver protect that goal harder.
A5: Goal | B5: Target | C5: Actual (link to Baseline Model) | D5: d- (shortfall) | E5: d+ (excess) | F5: Weight
A6: G1: Online fill rate >= 96% | B6: 0.96 | C6: ='Baseline Model'!B42 -> 1 | D6: =MAX(0,B6-C6) -> 0 | E6: =MAX(0,C6-B6) -> 0.04 | F6: 100
A7: G2: Store availability - online diversion <= 30% of store capacity (protects walk-in) | B7: 0.3 | C7: =SUM('Baseline Model'!B32:B36)/SUM('Baseline Model'!G32:G36) -> 0 | D7: =MAX(0,B7-C7) -> 0.3 | E7: =MAX(0,C7-B7) -> 0 | F7: 80
A8: G3: Fulfilment cost <= budget (Rs 2,150,000/month) | B8: 2150000 | C8: ='Baseline Model'!B41 -> 2119000 | D8: =MAX(0,B8-C8) -> 31000 | E8: =MAX(0,C8-B8) -> 0 | F8: 40
A9: G4: End-season markdown units <= 9% of inventory (current baseline) | B9: 0.09 | C9: 0.09 | D9: =MAX(0,B9-C9) -> 0 | E9: =MAX(0,C9-B9) -> 0 | F9: 60
A11: Weighted Goal Programming Objective (Solver target: minimize) | F11: =F6*(D6/B6) + F7*(E7/B7) + F8*(E8/B8) + F9*(E9/B9) -> 0
A13: Notes
B14: • Each deviation is normalized (divided by its target) before weighting, exactly like the percentage-deviation objective in the Session 19-20 slides - this stops the Rs-denominated cost goal from swamping the %-denominated service goals.
B15: • System constraints (warehouse & store capacity, Baseline Model Steps 3-4) still apply as HARD constraints in Solver - Goal Programming only relaxes the four listed GOALS, never physical capacity.
B16: • Raise a weight in column F to make Solver protect that goal more strongly; re-run Solver after any weight change.

Sheet Risk (Expected Value)
A1: Deliverables 4-5 — Risk Metrics (Model 5, Expected-Value form)
B3: These are single-point EXPECTED values computed directly from the probabilities in Exhibits 5-6 (equations 11-15 in the model doc). For full risk DISTRIBUTIONS (e.g. 90th percentile stockout risk), run a 1,000+ trial Monte Carlo - the Python script used to build this workbook can be extended to do that; ask and I'll generate it.
A5: Metric | B5: Expected Value | C5: Formula / logic
A6: Expected online return rate | B6: =Data!B46*Data!C46+Data!B47*Data!C47+Data!B48*Data!C48 -> 0.155 | C6: Probability-weighted average of Low/Normal/High return rates (Exhibit 6)
A7: Expected promo-driven online demand uplift | B7: =Data!B42*0.25 -> 0.0375 | C7: P(promo) x demand multiplier uplift (0.15 x 25%)
A8: Expected local-spike demand uplift (per store, unconditional) | B8: =Data!B52*Data!B51 -> 0.02 | C8: P(spike) x spike size (0.10 x 20%)
A9: Expected warehouse capacity loss (disruption) | B9: =Data!B54*Data!B53 -> 0.012 | C9: P(labor disruption) x capacity cut (0.08 x 15%)
A11: Applying these to the Baseline allocation:
A12: Expected effective warehouse capacity (Rs/month basis, units) | B12: =(Data!D5+Data!D6)*(1-B9) -> 53352
A13: Expected online demand incl. promo uplift (units) | B13: =SUM(Data!B15:B18)*(1+B7) -> 34237.5
A14: Warehouse-only headroom under this adverse scenario (units) | B14: =B12-B13 -> 19114.5
A15: Expected online lost sales if warehouses alone must absorb it (units) | B15: =MAX(0,-B14) -> 0
A16: -> Expected online lost-sale cost (Rs/month) | B16: =B15*Data!B33 -> 0
A17: Expected returned units (at baseline online demand) | B17: =SUM(Data!B15:B18)*B6 -> 5115
A18: of which immediately resaleable | B18: =B17*Data!B55 -> 3580.5
A19: of which incurs markdown-risk cost | B19: =B17*(1-Data!B55) -> 1534.5
A20: -> Expected markdown exposure (Rs/month) | B20: =B19*Data!B35 -> 168795
A21: -> Expected store-to-store transfer cost of returns rerouted to stores (Rs/month) | B21: =B17*Data!B55*0.5*Data!B36 -> 98463.75 | C21: Assumes ~50% of resaleable returns get transferred store-to-store rather than restocked in place - edit the 0.5 factor if you have a better estimate.
A23: Why this matters for the recommendation
A24: Under the MEAN-demand Baseline Model, warehouses alone have ~15,500 units of headroom (54,000 - 33,000) so ship-from-store adds almost nothing on cost. But once you stack the promo-surge uplift with the labor-disruption capacity cut (this sheet), that headroom compresses sharply - this is precisely the scenario where enabled stores (S2, S4, S5) function as a release valve. This is the quantitative basis for recommending SELECTIVE enablement (not separated, not fully pooled) as insurance against tail risk, even though the mean-case cost saving alone doesn't justify it.
